Workbook

Sheet Executive_Summary
B2: Godrej Consumer Products Ltd. Environmental & Decarbonization Dashboard (BRSR Core)
B4: SEBI BRSR environmental disclosures | FY 2022-23 to FY 2025-26 | Units: MJ, tCO₂e, KL, MT
B6: FY 2024-25
B8: ⚡ TOTAL ENERGY CONSUMED | E8: 📉 TOTAL GHG EMISSIONS (S1+S2+S3) | H8: 💧 WATER CONSUMPTION & REUSE | K8: ♻️ WASTE CIRCULARITY RATE
B9: =Calculations!G13 -> 898148494 | E9: =Calculations!G25 -> 2.261931 | H9: =Calculations!G39 -> 503608 | K9: =Calculations!G50 -> 0.72012739
B11: ="🌱 "&TEXT(Calculations!G14,"0.0%")&" renewable | "&IF(Calculations!$B$3=1,"base year",IF((Calculations!G13/INDEX(Calculations!C13:F13,Calculations!$B$3-1)-1)<0,"▼ ","▲ ")&TEXT(ABS((Calculations!G13/INDEX(Calculations!C13:F13,Calculations!$B$3-1)-1)),"0.0%")&" YoY") -> 🌱 44.6% renewable | ▲ 2.7% YoY | E11: =IF(ISNUMBER(Calculations!G26),"Scope 1 "&IF(Calculations!G26<0,"▼ ","▲ ")&TEXT(ABS(Calculations!G26),"0.0%")&" vs prior year","Scope 1: base year") -> Scope 1 ▼ 18.1% vs prior year | H11: ="♻ Reclaimed: "&TEXT(Calculations!G41,"#,##0")&" KL ("&TEXT(Calculations!G42,"0.0%")&" of total)" -> ♻ Reclaimed: 0 KL (0.0% of total) | K11: =TEXT(Calculations!G47,"#,##0")&" of "&TEXT(Calculations!G46,"#,##0")&" MT recycled" -> 5,395 of 7,492 MT recycled
B12: =TEXT(Calculations!G13,"#,##0")&" MJ" -> 89,81,48,494 MJ | E12: ="S1 "&TEXT(Calculations!G20/1000000,"0.000")&" | S2 "&TEXT(Calculations!G21/1000000,"0.000")&" | S3 "&TEXT(Calculations!G22/1000000,"0.000")&" Mt" -> S1 0.030 | S2 0.024 | S3 2.208 Mt | H12: ="Groundwater share: "&TEXT(Calculations!G40,"0.0%") -> Groundwater share: 67.8% | K12: ="Disposed "&TEXT(Calculations!G48,"#,##0.0")&" MT | Unclassified "&TEXT(Calculations!G49,"#,##0.0")&" MT" -> Disposed 69.2 MT | Unclassified 2,027.5 MT
B15: 📊 Energy Mix: Renewable vs Non-Renewable (million MJ) | H15: 📈 Decarbonization Trajectory: Scope 1 & 2 (bars) vs Scope 3 (line)
B33: 🌊 Water Conservation Shift: Groundwater vs Water Saved / Reclaimed (KL) | H33: ="🗑️ Waste Diversion, "&Calculations!B2 -> 🗑️ Waste Diversion, FY 2024-25
B52: Notes: (1) Waste donut shows Recycled, Disposed and Other / Not classified so slices always add to total generated. (2) Water Consumption is total withdrawal from all sources; Reclaimed is the sum of water-initiative savings in the raw data (none reported for FY 2022-23). (3) Scope 1 change is year-on-year; attribution to fuel-switch initiatives is not quantified in the BRSR data. Full assumptions: Calculations tab.

Sheet Raw_BRSR_Data
A1: S.No | B1: Category | C1: Metric | D1: Unit | E1: FY 2022-23 | F1: FY 2023-2024 | G1: FY 2024-2025 | H1: FY 2025-2026
A2: 1 | B2: Energy | C2: Total Energy from Renewable Sources | D2: MJ | E2: 246851828 | F2: 239056073 | G2: 400223723 | H2: 489955171
A3: 2 | B3: Energy | C3: Total Energy from Non-Renewable Sources | D3: MJ | E3: 603727451 | F3: 635397826 | G3: 497924771 | H3: 285642828
A4: 3 | B4: Energy | C4: Total Energy Consumed (Grand Total) | D4: MJ | E4: 850579279 | F4: 874453899 | G4: =SUM(G2:G3) -> 898148494 | H4: =SUM(H2:H3) -> 775597999
A5: 4 | B5: Energy | C5: Energy Intensity (per Rupee of Turnover) | D5: MJ/Rupee | E5: 0.011 | F5: 0.011 | G5: 0.01034 | H5: 0.00827
A6: 5 | B6: Energy | C6: Energy intensity (per MT of Product) | D6: MJ/MT | E6: 2558 | F6: 2367 | G6: 4185 | H6: 3963
A7: 6 | B7: Water | C7: Surface Water Withdrawal | D7: kl | E7: 0 | F7: 0 | G7: 0 | H7: 0
A8: 7 | B8: Water | C8: Groundwater Withdrawal | D8: kl | E8: 336755 | F8: 336136 | G8: 341690 | H8: 239306
A9: 8 | B9: Water | C9: Third Party Water Withdrawal | D9: kl | E9: 158665 | F9: 137797 | G9: 135229 | H9: 314779
A10: 9 | B10: Water | C10: Seawater / Desalinated Water | D10: kl | E10: 0 | F10: - | G10: - | H10: -
A11: 10 | B11: Water | C11: Rainwater / Others | D11: kl | E11: 1934946 | F11: 2053390 | G11: 26689 | H11: 38323
A12: 11 | B12: Water | C12: Total Water Consumption (Grand Total) | D12: kl | E12: 2430366 | F12: 2527323 | G12: =SUM(G7:G11) -> 503608 | H12: =SUM(H7:H11) -> 592408
A13: 12 | B13: Air Emissions | C13: NOx (Nitrogen Oxides) | D13: Tonnage (t) | E13: 88.8 | F13: 85 | G13: 21 | H13: 7
A14: 13 | B14: Air Emissions | C14: SOx (Sulphur Oxides) | D14: Tonnage (t) | E14: 136.4 | F14: 255 | G14: 1 | H14: 2
A15: 14 | B15: Air Emissions | C15: Particulate Matter (PM) | D15: Tonnage (t) | E15: 49.3 | F15: 60 | G15: 14 | H15: 15
A16: 15 | B16: Air Emissions | C16: Persistent Organic Pollutants (POP) | D16: N/A | E16: - | F16: - | G16: - | H16: -
A17: 16 | B17: Air Emissions | C17: Volatile Organic Compounds (VOC) | D17: N/A | E17: - | F17: - | G17: - | H17: -
B18: Air Emissions | C18: Hazardous Air Pollutants (HAP) | D18: N/A | E18: - | F18: - | G18: - | H18: -
A19: 17 | B19: Air Emissions | C19: Others | D19: N/A | E19: - | F19: - | G19: - | H19: -
A20: 18 | B20: GHG Emissions | C20: Total Scope 1 Emissions | D20: Metric tonnes of CO2 equivalent | E20: 33370 | F20: 36076 | G20: 29544 | H20: 11018
A21: 19 | B21: GHG Emissions | C21: Total Scope 2 Emissions | D21: Metric tonnes of CO2 equivalent | E21: 24643 | F21: 24362 | G21: 23932 | H21: 27247
A22: 20 | B22: GHG Emissions | C22: Total Scope 1 + Scope 2 Emissions (Sum) | D22: Metric tonnes of CO2 equivalent | E22: =SUM(E20:E21) -> 58013 | F22: =SUM(F20:F21) -> 60438 | G22: =SUM(G20:G21) -> 53476 | H22: =SUM(H20:H21) -> 38265
A23: 21 | B23: GHG Emissions | C23: Scope 1 & 2 Emission Intensity (per Rupee of Turnover) | D23: MT CO2 eq. / Rupee | E23: 8e-07 | F23: 7e-07 | G23: 6e-07 | H23: 4e-07
A24: 22 | B24: GHG Emissions | C24: Scope 1 & 2 Emission Intensity adjusted for PPP | D24: MT CO2 eq. / USD | E24: 1.8e-06 | F24: 1.5e-06 | G24: 1.3e-06 | H24: 8e-06
A25: 23 | B25: GHG Emissions | C25: Scope 1 & 2 Emission Intensity (in terms of Physical Output) | D25: MT CO2 eq. / MT of Product | E25: 0.17 | F25: 0.16 | G25: 0.25 | H25: 0.2
A26: 24 | B26: Waste | C26: Plastic Waste | D26: Metric Tonnes | E26: 1339 | F26: 1029 | G26: 1340 | H26: 1487
A27: 25 | B27: Waste | C27: E-Waste | D27: Metric Tonnes | E27: 2 | F27: 1.34 | G27: 1.94 | H27: 0.99
A28: 26 | B28: Waste | C28: Bio-medical Waste | D28: Metric Tonnes | E28: 0 | F28: 0 | G28: 0.49 | H28: 0.76
A29: 27 | B29: Waste | C29: Construction & Demolition Waste | D29: Metric Tonnes | E29: 0 | F29: 0 | G29: - | H29: -
A30: 28 | B30: Waste | C30: Battery Waste | D30: Metric Tonnes | E30: 0 | F30: 0.18 | G30: 2.3 | H30: 0.4
A31: 29 | B31: Waste | C31: Radioactive Waste | D31: Metric Tonnes | E31: 0 | F31: 0 | G31: - | H31: -
A32: 30 | B32: Waste | C32: Other Hazardous Waste | D32: Metric Tonnes | E32: 235 | F32: 409 | G32: 228 | H32: 405
A33: 31 | B33: Waste | C33: Other Non-Hazardous Waste | D33: Metric Tonnes | E33: 3560 | F33: 2458 | G33: 5919 | H33: 4416
B34: Waste | C34: Total Waste Generated | D34: Metric Tonnes | E34: =SUM(E26:E33) -> 5136 | F34: =SUM(F26:F33) -> 3897.52 | G34: =SUM(G26:G33) -> 7491.73 | H34: =SUM(H26:H33) -> 6310.15
B35: Waste | C35: Waste Recycled | D35: Metric Tonnes | E35: 4223 | F35: 3482 | G35: 5395 | H35: 6189
B36: Waste | C36: Waste Disposed | D36: Metric Tonnes | E36: 97 | F36: 5.33 | G36: 69.2 | H36: 4.54
B37: Waste | C37: Waste Intensity (per Rupee of Turnover) | D37: MT / Rupee | E37: 6.8e-08 | F37: 4.7e-08 | G37: 8.6e-08 | H37: 6.7e-08
B38: Waste | C38: Waste Intensity | D38: MT / MT | E38: 0.02 | F38: 0.01 | G38: 0.02 | H38: 0.03
B39: GHG Emissions | C39: Total Scope 3 Emissions | D39: Metric tonnes of CO2 equivalent | E39: 1333796 | F39: 1482327 | G39: 2208455 | H39: 1818735
B40: GHG Emissions | C40: Total Scope 3 Emissions per Rupee of Turnover | D40: MT CO2 eq. / Rupee | E40: 1.8e-05 | F40: 1.8e-05 | G40: 2.5e-05 | H40: 1.9e-05
...

Sheet Calculations
A1: Calculations
A2: Selected year (from dashboard dropdown) | B2: =Executive_Summary!B6 -> FY 2024-25
A3: Selected year position (1-4) | B3: =MATCH(B2,$A$5:$A$8,0) -> 3
A4: Dashboard label | B4: Raw sheet header | C4: Raw column
A5: FY 2022-23 | B5: =Raw_BRSR_Data!E1 -> FY 2022-23 | C5: 1
A6: FY 2023-24 | B6: =Raw_BRSR_Data!F1 -> FY 2023-2024 | C6: 2
A7: FY 2024-25 | B7: =Raw_BRSR_Data!G1 -> FY 2024-2025 | C7: 3
A8: FY 2025-26 | B8: =Raw_BRSR_Data!H1 -> FY 2025-2026 | C8: 4
C9: =$C$5 -> 1 | D9: =$C$6 -> 2 | E9: =$C$7 -> 3 | F9: =$C$8 -> 4
A10: 1. ENERGY | B10: Unit | C10: =$A$5 -> FY 2022-23 | D10: =$A$6 -> FY 2023-24 | E10: =$A$7 -> FY 2024-25 | F10: =$A$8 -> FY 2025-26 | G10: ="Selected: "&$B$2 -> Selected: FY 2024-25 | H10: Source metric (Raw_BRSR_Data)
A11: Renewable Energy | B11: MJ | C11: =SUMIFS(INDEX(Raw_BRSR_Data!$E$2:$H$118,0,C$9),Raw_BRSR_Data!$C$2:$C$118,$H11) -> 246851828 | D11: =SUMIFS(INDEX(Raw_BRSR_Data!$E$2:$H$118,0,D$9),Raw_BRSR_Data!$C$2:$C$118,$H11) -> 239056073 | E11: =SUMIFS(INDEX(Raw_BRSR_Data!$E$2:$H$118,0,E$9),Raw_BRSR_Data!$C$2:$C$118,$H11) -> 400223723 | F11: =SUMIFS(INDEX(Raw_BRSR_Data!$E$2:$H$118,0,F$9),Raw_BRSR_Data!$C$2:$C$118,$H11) -> 489955171 | G11: =INDEX(C11:F11,$B$3) -> 400223723 | H11: Total Energy from Renewable Sources
A12: Non-Renewable Energy | B12: MJ | C12: =SUMIFS(INDEX(Raw_BRSR_Data!$E$2:$H$118,0,C$9),Raw_BRSR_Data!$C$2:$C$118,$H12) -> 603727451 | D12: =SUMIFS(INDEX(Raw_BRSR_Data!$E$2:$H$118,0,D$9),Raw_BRSR_Data!$C$2:$C$118,$H12) -> 635397826 | E12: =SUMIFS(INDEX(Raw_BRSR_Data!$E$2:$H$118,0,E$9),Raw_BRSR_Data!$C$2:$C$118,$H12) -> 497924771 | F12: =SUMIFS(INDEX(Raw_BRSR_Data!$E$2:$H$118,0,F$9),Raw_BRSR_Data!$C$2:$C$118,$H12) -> 285642828 | G12: =INDEX(C12:F12,$B$3) -> 497924771 | H12: Total Energy from Non-Renewable Sources
A13: Total Energy Consumed | B13: MJ | C13: =C11+C12 -> 850579279 | D13: =D11+D12 -> 874453899 | E13: =E11+E12 -> 898148494 | F13: =F11+F12 -> 775597999 | G13: =INDEX(C13:F13,$B$3) -> 898148494 | H13: Renewable + non-renewable
A14: Renewable Share | B14: % | C14: =IFERROR(C11/C13,0) -> 0.29021613 | D14: =IFERROR(D11/D13,0) -> 0.27337756 | E14: =IFERROR(E11/E13,0) -> 0.44560975 | F14: =IFERROR(F11/F13,0) -> 0.63171278 | G14: =INDEX(C14:F14,$B$3) -> 0.44560975
A15: Energy Intensity (per Rupee of Turnover) | B15: MJ/Rupee | C15: =SUMIFS(INDEX(Raw_BRSR_Data!$E$2:$H$118,0,C$9),Raw_BRSR_Data!$C$2:$C$118,$H15) -> 0.011 | D15: =SUMIFS(INDEX(Raw_BRSR_Data!$E$2:$H$118,0,D$9),Raw_BRSR_Data!$C$2:$C$118,$H15) -> 0.011 | E15: =SUMIFS(INDEX(Raw_BRSR_Data!$E$2:$H$118,0,E$9),Raw_BRSR_Data!$C$2:$C$118,$H15) -> 0.01034 | F15: =SUMIFS(INDEX(Raw_BRSR_Data!$E$2:$H$118,0,F$9),Raw_BRSR_Data!$C$2:$C$118,$H15) -> 0.00827 | G15: =INDEX(C15:F15,$B$3) -> 0.01034 | H15: Energy Intensity (per Rupee of Turnover)
A16: Energy Intensity (per MT of Product) | B16: MJ/MT | C16: =SUMIFS(INDEX(Raw_BRSR_Data!$E$2:$H$118,0,C$9),Raw_BRSR_Data!$C$2:$C$118,$H16) -> 2558 | D16: =SUMIFS(INDEX(Raw_BRSR_Data!$E$2:$H$118,0,D$9),Raw_BRSR_Data!$C$2:$C$118,$H16) -> 2367 | E16: =SUMIFS(INDEX(Raw_BRSR_Data!$E$2:$H$118,0,E$9),Raw_BRSR_Data!$C$2:$C$118,$H16) -> 4185 | F16: =SUMIFS(INDEX(Raw_BRSR_Data!$E$2:$H$118,0,F$9),Raw_BRSR_Data!$C$2:$C$118,$H16) -> 3963 | G16: =INDEX(C16:F16,$B$3) -> 4185 | H16: Energy intensity (per MT of Product)
A19: 2. EMISSIONS | B19: Unit | C19: =$A$5 -> FY 2022-23 | D19: =$A$6 -> FY 2023-24 | E19: =$A$7 -> FY 2024-25 | F19: =$A$8 -> FY 2025-26 | G19: ="Selected: "&$B$2 -> Selected: FY 2024-25 | H19: Source metric (Raw_BRSR_Data)
A20: Scope 1 Emissions | B20: tCO2e | C20: =SUMIFS(INDEX(Raw_BRSR_Data!$E$2:$H$118,0,C$9),Raw_BRSR_Data!$C$2:$C$118,$H20) -> 33370 | D20: =SUMIFS(INDEX(Raw_BRSR_Data!$E$2:$H$118,0,D$9),Raw_BRSR_Data!$C$2:$C$118,$H20) -> 36076 | E20: =SUMIFS(INDEX(Raw_BRSR_Data!$E$2:$H$118,0,E$9),Raw_BRSR_Data!$C$2:$C$118,$H20) -> 29544 | F20: =SUMIFS(INDEX(Raw_BRSR_Data!$E$2:$H$118,0,F$9),Raw_BRSR_Data!$C$2:$C$118,$H20) -> 11018 | G20: =INDEX(C20:F20,$B$3) -> 29544 | H20: Total Scope 1 Emissions
A21: Scope 2 Emissions | B21: tCO2e | C21: =SUMIFS(INDEX(Raw_BRSR_Data!$E$2:$H$118,0,C$9),Raw_BRSR_Data!$C$2:$C$118,$H21) -> 24643 | D21: =SUMIFS(INDEX(Raw_BRSR_Data!$E$2:$H$118,0,D$9),Raw_BRSR_Data!$C$2:$C$118,$H21) -> 24362 | E21: =SUMIFS(INDEX(Raw_BRSR_Data!$E$2:$H$118,0,E$9),Raw_BRSR_Data!$C$2:$C$118,$H21) -> 23932 | F21: =SUMIFS(INDEX(Raw_BRSR_Data!$E$2:$H$118,0,F$9),Raw_BRSR_Data!$C$2:$C$118,$H21) -> 27247 | G21: =INDEX(C21:F21,$B$3) -> 23932 | H21: Total Scope 2 Emissions
A22: Scope 3 Emissions | B22: tCO2e | C22: =SUMIFS(INDEX(Raw_BRSR_Data!$E$2:$H$118,0,C$9),Raw_BRSR_Data!$C$2:$C$118,$H22) -> 1333796 | D22: =SUMIFS(INDEX(Raw_BRSR_Data!$E$2:$H$118,0,D$9),Raw_BRSR_Data!$C$2:$C$118,$H22) -> 1482327 | E22: =SUMIFS(INDEX(Raw_BRSR_Data!$E$2:$H$118,0,E$9),Raw_BRSR_Data!$C$2:$C$118,$H22) -> 2208455 | F22: =SUMIFS(INDEX(Raw_BRSR_Data!$E$2:$H$118,0,F$9),Raw_BRSR_Data!$C$2:$C$118,$H22) -> 1818735 | G22: =INDEX(C22:F22,$B$3) -> 2208455 | H22: Total Scope 3 Emissions
A23: Scope 1 + Scope 2 | B23: tCO2e | C23: =C20+C21 -> 58013 | D23: =D20+D21 -> 60438 | E23: =E20+E21 -> 53476 | F23: =F20+F21 -> 38265 | G23: =INDEX(C23:F23,$B$3) -> 53476
A24: Total GHG (Scope 1 + 2 + 3) | B24: tCO2e | C24: =C23+C22 -> 1391809 | D24: =D23+D22 -> 1542765 | E24: =E23+E22 -> 2261931 | F24: =F23+F22 -> 1857000 | G24: =INDEX(C24:F24,$B$3) -> 2261931
A25: Total GHG (Scope 1 + 2 + 3) | B25: MtCO2e | C25: =C24/1000000 -> 1.391809 | D25: =D24/1000000 -> 1.542765 | E25: =E24/1000000 -> 2.261931 | F25: =F24/1000000 -> 1.857 | G25: =INDEX(C25:F25,$B$3) -> 2.261931 | H25: tCO2e divided by 1,000,000
A26: Scope 1 change vs previous year | B26: % | C26: Base year | D26: =IFERROR(D20/C20-1,0) -> 0.0810908 | E26: =IFERROR(E20/D20-1,0) -> -0.1810622 | F26: =IFERROR(F20/E20-1,0) -> -0.62706472 | G26: =INDEX(C26:F26,$B$3) -> -0.1810622
A27: Scope 1 & 2 Intensity (per Rupee of Turnover) | B27: MT CO2e/Rupee | C27: =SUMIFS(INDEX(Raw_BRSR_Data!$E$2:$H$118,0,C$9),Raw_BRSR_Data!$C$2:$C$118,$H27) -> 8e-07 | D27: =SUMIFS(INDEX(Raw_BRSR_Data!$E$2:$H$118,0,D$9),Raw_BRSR_Data!$C$2:$C$118,$H27) -> 7e-07 | E27: =SUMIFS(INDEX(Raw_BRSR_Data!$E$2:$H$118,0,E$9),Raw_BRSR_Data!$C$2:$C$118,$H27) -> 6e-07 | F27: =SUMIFS(INDEX(Raw_BRSR_Data!$E$2:$H$118,0,F$9),Raw_BRSR_Data!$C$2:$C$118,$H27) -> 4e-07 | G27: =INDEX(C27:F27,$B$3) -> 6e-07 | H27: Scope 1 & 2 Emission Intensity (per Rupee of Turnover)
A28: Scope 1 & 2 Intensity (per MT of Product) | B28: MT CO2e/MT | C28: =SUMIFS(INDEX(Raw_BRSR_Data!$E$2:$H$118,0,C$9),Raw_BRSR_Data!$C$2:$C$118,$H28) -> 0.17 | D28: =SUMIFS(INDEX(Raw_BRSR_Data!$E$2:$H$118,0,D$9),Raw_BRSR_Data!$C$2:$C$118,$H28) -> 0.16 | E28: =SUMIFS(INDEX(Raw_BRSR_Data!$E$2:$H$118,0,E$9),Raw_BRSR_Data!$C$2:$C$118,$H28) -> 0.25 | F28: =SUMIFS(INDEX(Raw_BRSR_Data!$E$2:$H$118,0,F$9),Raw_BRSR_Data!$C$2:$C$118,$H28) -> 0.2 | G28: =INDEX(C28:F28,$B$3) -> 0.25 | H28: Scope 1 & 2 Emission Intensity (in terms of Physical Output)
A29: Scope 3 Intensity (per Rupee of Turnover) | B29: MT CO2e/Rupee | C29: =SUMIFS(INDEX(Raw_BRSR_Data!$E$2:$H$118,0,C$9),Raw_BRSR_Data!$C$2:$C$118,$H29) -> 1.8e-05 | D29: =SUMIFS(INDEX(Raw_BRSR_Data!$E$2:$H$118,0,D$9),Raw_BRSR_Data!$C$2:$C$118,$H29) -> 1.8e-05 | E29: =SUMIFS(INDEX(Raw_BRSR_Data!$E$2:$H$118,0,E$9),Raw_BRSR_Data!$C$2:$C$118,$H29) -> 2.5e-05 | F29: =SUMIFS(INDEX(Raw_BRSR_Data!$E$2:$H$118,0,F$9),Raw_BRSR_Data!$C$2:$C$118,$H29) -> 1.9e-05 | G29: =INDEX(C29:F29,$B$3) -> 2.5e-05 | H29: Total Scope 3 Emissions per Rupee of Turnover
A30: Scope 3 Intensity (per MT of Product) | B30: MT CO2e/MT | C30: =SUMIFS(INDEX(Raw_BRSR_Data!$E$2:$H$118,0,C$9),Raw_BRSR_Data!$C$2:$C$118,$H30) -> 4.01 | D30: =SUMIFS(INDEX(Raw_BRSR_Data!$E$2:$H$118,0,D$9),Raw_BRSR_Data!$C$2:$C$118,$H30) -> 4.01 | E30: =SUMIFS(INDEX(Raw_BRSR_Data!$E$2:$H$118,0,E$9),Raw_BRSR_Data!$C$2:$C$118,$H30) -> 10.29 | F30: =SUMIFS(INDEX(Raw_BRSR_Data!$E$2:$H$118,0,F$9),Raw_BRSR_Data!$C$2:$C$118,$H30) -> 9.29 | G30: =INDEX(C30:F30,$B$3) -> 10.29 | H30: Total Scope 3 Emission Intensity (Physical Output)
A33: 3a. WATER | B33: Unit | C33: =$A$5 -> FY 2022-23 | D33: =$A$6 -> FY 2023-24 | E33: =$A$7 -> FY 2024-25 | F33: =$A$8 -> FY 2025-26 | G33: ="Selected: "&$B$2 -> Selected: FY 2024-25 | H33: Source metric (Raw_BRSR_Data)
A34: Surface Water Withdrawal | B34: kl | C34: =SUMIFS(INDEX(Raw_BRSR_Data!$E$2:$H$118,0,C$9),Raw_BRSR_Data!$C$2:$C$118,$H34) -> 0 | D34: =SUMIFS(INDEX(Raw_BRSR_Data!$E$2:$H$118,0,D$9),Raw_BRSR_Data!$C$2:$C$118,$H34) -> 0 | E34: =SUMIFS(INDEX(Raw_BRSR_Data!$E$2:$H$118,0,E$9),Raw_BRSR_Data!$C$2:$C$118,$H34) -> 0 | F34: =SUMIFS(INDEX(Raw_BRSR_Data!$E$2:$H$118,0,F$9),Raw_BRSR_Data!$C$2:$C$118,$H34) -> 0 | G34: =INDEX(C34:F34,$B$3) -> 0 | H34: Surface Water Withdrawal
A35: Groundwater Withdrawal | B35: kl | C35: =SUMIFS(INDEX(Raw_BRSR_Data!$E$2:$H$118,0,C$9),Raw_BRSR_Data!$C$2:$C$118,$H35) -> 336755 | D35: =SUMIFS(INDEX(Raw_BRSR_Data!$E$2:$H$118,0,D$9),Raw_BRSR_Data!$C$2:$C$118,$H35) -> 336136 | E35: =SUMIFS(INDEX(Raw_BRSR_Data!$E$2:$H$118,0,E$9),Raw_BRSR_Data!$C$2:$C$118,$H35) -> 341690 | F35: =SUMIFS(INDEX(Raw_BRSR_Data!$E$2:$H$118,0,F$9),Raw_BRSR_Data!$C$2:$C$118,$H35) -> 239306 | G35: =INDEX(C35:F35,$B$3) -> 341690 | H35: Groundwater Withdrawal
A36: Third Party Water Withdrawal | B36: kl | C36: =SUMIFS(INDEX(Raw_BRSR_Data!$E$2:$H$118,0,C$9),Raw_BRSR_Data!$C$2:$C$118,$H36) -> 158665 | D36: =SUMIFS(INDEX(Raw_BRSR_Data!$E$2:$H$118,0,D$9),Raw_BRSR_Data!$C$2:$C$118,$H36) -> 137797 | E36: =SUMIFS(INDEX(Raw_BRSR_Data!$E$2:$H$118,0,E$9),Raw_BRSR_Data!$C$2:$C$118,$H36) -> 135229 | F36: =SUMIFS(INDEX(Raw_BRSR_Data!$E$2:$H$118,0,F$9),Raw_BRSR_Data!$C$2:$C$118,$H36) -> 314779 | G36: =INDEX(C36:F36,$B$3) -> 135229 | H36: Third Party Water Withdrawal
A37: Seawater / Desalinated Water | B37: kl | C37: =SUMIFS(INDEX(Raw_BRSR_Data!$E$2:$H$118,0,C$9),Raw_BRSR_Data!$C$2:$C$118,$H37) -> 0 | D37: =SUMIFS(INDEX(Raw_BRSR_Data!$E$2:$H$118,0,D$9),Raw_BRSR_Data!$C$2:$C$118,$H37) -> 0 | E37: =SUMIFS(INDEX(Raw_BRSR_Data!$E$2:$H$118,0,E$9),Raw_BRSR_Data!$C$2:$C$118,$H37) -> 0 | F37: =SUMIFS(INDEX(Raw_BRSR_Data!$E$2:$H$118,0,F$9),Raw_BRSR_Data!$C$2:$C$118,$H37) -> 0 | G37: =INDEX(C37:F37,$B$3) -> 0 | H37: Seawater / Desalinated Water
A38: Rainwater / Others | B38: kl | C38: =SUMIFS(INDEX(Raw_BRSR_Data!$E$2:$H$118,0,C$9),Raw_BRSR_Data!$C$2:$C$118,$H38) -> 1934946 | D38: =SUMIFS(INDEX(Raw_BRSR_Data!$E$2:$H$118,0,D$9),Raw_BRSR_Data!$C$2:$C$118,$H38) -> 2053390 | E38: =SUMIFS(INDEX(Raw_BRSR_Data!$E$2:$H$118,0,E$9),Raw_BRSR_Data!$C$2:$C$118,$H38) -> 26689 | F38: =SUMIFS(INDEX(Raw_BRSR_Data!$E$2:$H$118,0,F$9),Raw_BRSR_Data!$C$2:$C$118,$H38) -> 38323 | G38: =INDEX(C38:F38,$B$3) -> 26689 | H38: Rainwater / Others
A39: Total Water Consumption | B39: kl | C39: =SUM(C34:C38) -> 2430366 | D39: =SUM(D34:D38) -> 2527323 | E39: =SUM(E34:E38) -> 503608 | F39: =SUM(F34:F38) -> 592408 | G39: =INDEX(C39:F39,$B$3) -> 503608
A40: Groundwater Share of Total | B40: % | C40: =IFERROR(C35/C39,0) -> 0.13856143 | D40: =IFERROR(D35/D39,0) -> 0.13300081 | E40: =IFERROR(E35/E39,0) -> 0.67848406 | F40: =IFERROR(F35/F39,0) -> 0.40395471 | G40: =INDEX(C40:F40,$B$3) -> 0.67848406
A41: Water Saved / Reclaimed via Initiatives | B41: KL | C41: =SUMIFS(INDEX(Raw_BRSR_Data!$E$2:$H$118,0,C$9),Raw_BRSR_Data!$C$2:$C$118,$H41)+SUMIFS(INDEX(Raw_BRSR_Data!$E$2:$H$118,0,C$9),Raw_BRSR_Data!$C$2:$C$118,$I41) -> 0 | D41: =SUMIFS(INDEX(Raw_BRSR_Data!$E$2:$H$118,0,D$9),Raw_BRSR_Data!$C$2:$C$118,$H41)+SUMIFS(INDEX(Raw_BRSR_Data!$E$2:$H$118,0,D$9),Raw_BRSR_Data!$C$2:$C$118,$I41) -> 1129 | E41: =SUMIFS(INDEX(Raw_BRSR_Data!$E$2:$H$118,0,E$9),Raw_BRSR_Data!$C$2:$C$118,$H41)+SUMIFS(INDEX(Raw_BRSR_Data!$E$2:$H$118,0,E$9),Raw_BRSR_Data!$C$2:$C$118,$I41) -> 0 | F41: =SUMIFS(INDEX(Raw_BRSR_Data!$E$2:$H$118,0,F$9),Raw_BRSR_Data!$C$2:$C$118,$H41)+SUMIFS(INDEX(Raw_BRSR_Data!$E$2:$H$118,0,F$9),Raw_BRSR_Data!$C$2:$C$118,$I41) -> 36300 | G41: =INDEX(C41:F41,$B$3) -> 0 | H41: Total Water Saved
A42: Reclaimed Share of Total Water | B42: % | C42: =IFERROR(C41/C39,0) -> 0 | D42: =IFERROR(D41/D39,0) -> 0.00044671773 | E42: =IFERROR(E41/E39,0) -> 0 | F42: =IFERROR(F41/F39,0) -> 0.061275337 | G42: =INDEX(C42:F42,$B$3) -> 0
A45: 3b. WASTE | B45: Unit | C45: =$A$5 -> FY 2022-23 | D45: =$A$6 -> FY 2023-24 | E45: =$A$7 -> FY 2024-25 | F45: =$A$8 -> FY 2025-26 | G45: ="Selected: "&$B$2 -> Selected: FY 2024-25 | H45: Source metric (Raw_BRSR_Data)
A46: Total Waste Generated | B46: MT | C46: =SUM(INDEX(Raw_BRSR_Data!$E$26:$H$33,0,C$9)) -> 5136 | D46: =SUM(INDEX(Raw_BRSR_Data!$E$26:$H$33,0,D$9)) -> 3897.52 | E46: =SUM(INDEX(Raw_BRSR_Data!$E$26:$H$33,0,E$9)) -> 7491.73 | F46: =SUM(INDEX(Raw_BRSR_Data!$E$26:$H$33,0,F$9)) -> 6310.15 | G46: =INDEX(C46:F46,$B$3) -> 7491.73 | H46: Sum of Raw_BRSR_Data rows 26-33 (eight waste types)
...

Sheet Initiatives_Tracker
A1: Sustainability Initiatives Tracker
A2: Project ID | B2: Category | C2: Initiative Name | D2: Location/Unit | E2: Savings (kWh/KL/GJ) | F2: Impact/Remarks
A3: EN-01 | B3: Energy | C3: =Raw_BRSR_Data!C88 -> Co-Generation - 25 TPH Steam and 1.5 MW Power | D3: Not specified | E3: =Raw_BRSR_Data!H88 -> 2000000 | F3: ="kWh | "&TEXT(E3/SUMIFS($E$3:$E$30,$B$3:$B$30,B3),"0.0%")&" of FY 2025-26 energy total" -> kWh | 52.8% of FY 2025-26 energy total
A4: EN-02 | B4: Energy | C4: =Raw_BRSR_Data!C89 -> Self-consumed electrical energy reduction in CoGen Plant by 12% | D4: CoGen Plant | E4: =Raw_BRSR_Data!H89 -> 450000 | F4: ="kWh | "&TEXT(E4/SUMIFS($E$3:$E$30,$B$3:$B$30,B4),"0.0%")&" of FY 2025-26 energy total" -> kWh | 11.9% of FY 2025-26 energy total
A5: EN-03 | B5: Energy | C5: =Raw_BRSR_Data!C90 -> Air Compressor Specific Power Reduction by 25% for GERC Malanpur | D5: GERC, Malanpur | E5: =Raw_BRSR_Data!H90 -> 240000 | F5: ="kWh | "&TEXT(E5/SUMIFS($E$3:$E$30,$B$3:$B$30,B5),"0.0%")&" of FY 2025-26 energy total" -> kWh | 6.3% of FY 2025-26 energy total
A6: EN-04 | B6: Energy | C6: =Raw_BRSR_Data!C91 -> Dedicated Brine chiller for Unit 2 | D6: Unit 2 | E6: =Raw_BRSR_Data!H91 -> 210000 | F6: ="kWh | "&TEXT(E6/SUMIFS($E$3:$E$30,$B$3:$B$30,B6),"0.0%")&" of FY 2025-26 energy total" -> kWh | 5.5% of FY 2025-26 energy total
A7: EN-05 | B7: Energy | C7: =Raw_BRSR_Data!C92 -> Chiller replacement 110 TR by energy efficient 130 TR | D7: Not specified | E7: =Raw_BRSR_Data!H92 -> 200000 | F7: ="kWh | "&TEXT(E7/SUMIFS($E$3:$E$30,$B$3:$B$30,B7),"0.0%")&" of FY 2025-26 energy total" -> kWh | 5.3% of FY 2025-26 energy total
A8: EN-06 | B8: Energy | C8: =Raw_BRSR_Data!C93 -> Energy Efficient Shrink Tunnel Machine Installation | D8: Not specified | E8: =Raw_BRSR_Data!H93 -> 104706 | F8: ="kWh | "&TEXT(E8/SUMIFS($E$3:$E$30,$B$3:$B$30,B8),"0.0%")&" of FY 2025-26 energy total" -> kWh | 2.8% of FY 2025-26 energy total
A9: EN-07 | B9: Energy | C9: =Raw_BRSR_Data!C94 -> Energy Efficient Wall Fans Installation | D9: Not specified | E9: =Raw_BRSR_Data!H94 -> 100000 | F9: ="kWh | "&TEXT(E9/SUMIFS($E$3:$E$30,$B$3:$B$30,B9),"0.0%")&" of FY 2025-26 energy total" -> kWh | 2.6% of FY 2025-26 energy total
A10: EN-08 | B10: Energy | C10: =Raw_BRSR_Data!C95 -> Eliminated spiral conveyor & installed flat conveyor for packing | D10: Not specified | E10: =Raw_BRSR_Data!H95 -> 92400 | F10: ="kWh | "&TEXT(E10/SUMIFS($E$3:$E$30,$B$3:$B$30,B10),"0.0%")&" of FY 2025-26 energy total" -> kWh | 2.4% of FY 2025-26 energy total
A11: EN-09 | B11: Energy | C11: =Raw_BRSR_Data!C96 -> Energy Efficient Exhaust Fans Installation | D11: Not specified | E11: =Raw_BRSR_Data!H96 -> 83047 | F11: ="kWh | "&TEXT(E11/SUMIFS($E$3:$E$30,$B$3:$B$30,B11),"0.0%")&" of FY 2025-26 energy total" -> kWh | 2.2% of FY 2025-26 energy total
A12: EN-10 | B12: Energy | C12: =Raw_BRSR_Data!C97 -> Interlocking of S conveyor with wrapping machine | D12: Not specified | E12: =Raw_BRSR_Data!H97 -> 61600 | F12: ="kWh | "&TEXT(E12/SUMIFS($E$3:$E$30,$B$3:$B$30,B12),"0.0%")&" of FY 2025-26 energy total" -> kWh | 1.6% of FY 2025-26 energy total
A13: EN-11 | B13: Energy | C13: =Raw_BRSR_Data!C98 -> Chiller and CT interlocking in GERC | D13: GERC | E13: =Raw_BRSR_Data!H98 -> 50000 | F13: ="kWh | "&TEXT(E13/SUMIFS($E$3:$E$30,$B$3:$B$30,B13),"0.0%")&" of FY 2025-26 energy total" -> kWh | 1.3% of FY 2025-26 energy total
A14: EN-12 | B14: Energy | C14: =Raw_BRSR_Data!C99 -> 37KW mixer motor replaced with 30kw motor | D14: Not specified | E14: =Raw_BRSR_Data!H99 -> 44100 | F14: ="kWh | "&TEXT(E14/SUMIFS($E$3:$E$30,$B$3:$B$30,B14),"0.0%")&" of FY 2025-26 energy total" -> kWh | 1.2% of FY 2025-26 energy total
... A23: EN-21 | B23: Energy | C23: =Raw_BRSR_Data!C108 -> IE 2 to IE 4 energy saving motor changed | D23: Not specified | E23: =Raw_BRSR_Data!H108 -> 3599 | F23: ="kWh | "&TEXT(E23/SUMIFS($E$3:$E$30,$B$3:$B$30,B23),"0.0%")&" of FY 2025-26 energy total" -> kWh | 0.1% of FY 2025-26 energy total
A24: WA-01 | B24: Water | C24: =Raw_BRSR_Data!C110 -> Reused for Cogen RO Reject water of TDS around 500 | D24: CoGen | E24: =Raw_BRSR_Data!H110 -> 15000 | F24: ="KL | "&TEXT(E24/SUMIFS($E$3:$E$30,$B$3:$B$30,B24),"0.0%")&" of FY 2025-26 water total" -> KL | 41.3% of FY 2025-26 water total
A25: WA-02 | B25: Water | C25: =Raw_BRSR_Data!C111 -> All taps replaced with water efficient taps in Malanpur plant | D25: Malanpur plant | E25: =Raw_BRSR_Data!H111 -> 9900 | F25: ="KL | "&TEXT(E25/SUMIFS($E$3:$E$30,$B$3:$B$30,B25),"0.0%")&" of FY 2025-26 water total" -> KL | 27.3% of FY 2025-26 water total
A26: WA-03 | B26: Water | C26: =Raw_BRSR_Data!C112 -> Condensate water reuse in CSP/New CSP | D26: CSP / New CSP | E26: =Raw_BRSR_Data!H112 -> 6000 | F26: ="KL | "&TEXT(E26/SUMIFS($E$3:$E$30,$B$3:$B$30,B26),"0.0%")&" of FY 2025-26 water total" -> KL | 16.5% of FY 2025-26 water total
A27: WA-04 | B27: Water | C27: =Raw_BRSR_Data!C113 -> Turbine blowdown condensate water reutilisation in Cogen | D27: CoGen | E27: =Raw_BRSR_Data!H113 -> 3240 | F27: ="KL | "&TEXT(E27/SUMIFS($E$3:$E$30,$B$3:$B$30,B27),"0.0%")&" of FY 2025-26 water total" -> KL | 8.9% of FY 2025-26 water total
A28: WA-05 | B28: Water | C28: =Raw_BRSR_Data!C114 -> Reclaimed Filter Backwash at Water Treatment Plant | D28: Water Treatment Plant | E28: =Raw_BRSR_Data!H114 -> 2160 | F28: ="KL | "&TEXT(E28/SUMIFS($E$3:$E$30,$B$3:$B$30,B28),"0.0%")&" of FY 2025-26 water total" -> KL | 6.0% of FY 2025-26 water total
A29: FU-01 | B29: Fuel | C29: =Raw_BRSR_Data!C116 -> Electric Boiler for Ilicit | D29: Not specified | E29: =Raw_BRSR_Data!H116 -> 11467 | F29: ="Unit not stated in source | "&TEXT(E29/SUMIFS($E$3:$E$30,$B$3:$B$30,B29),"0.0%")&" of FY 2025-26 fuel total" -> Unit not stated in source | 81.3% of FY 2025-26 fuel total
A30: FU-02 | B30: Fuel | C30: =Raw_BRSR_Data!C117 -> Usage of Biodiesel in Boiler | D30: Boiler | E30: =Raw_BRSR_Data!H117 -> 2636 | F30: ="Unit not stated in source | "&TEXT(E30/SUMIFS($E$3:$E$30,$B$3:$B$30,B30),"0.0%")&" of FY 2025-26 fuel total" -> Unit not stated in source | 18.7% of FY 2025-26 fuel total
A32: Category totals & reconciliation with Raw_BRSR_Data
A33: Category | B33: Projects | C33: Total Savings | D33: Raw sheet total | E33: Difference (should be 0)
A34: Energy | B34: =COUNTIFS($B$3:$B$30,A34) -> 21 | C34: =SUMIFS($E$3:$E$30,$B$3:$B$30,A34) -> 3785076 | D34: =Raw_BRSR_Data!H109 -> 3785076 | E34: =C34-D34 -> 0
A35: Water | B35: =COUNTIFS($B$3:$B$30,A35) -> 5 | C35: =SUMIFS($E$3:$E$30,$B$3:$B$30,A35) -> 36300 | D35: =Raw_BRSR_Data!H115 -> 36300 | E35: =C35-D35 -> 0
A36: Fuel | B36: =COUNTIFS($B$3:$B$30,A36) -> 2 | C36: =SUMIFS($E$3:$E$30,$B$3:$B$30,A36) -> 14103 | D36: =Raw_BRSR_Data!H118 -> 14103 | E36: =C36-D36 -> 0
A37: Totals are in different units (kWh, KL, unit not stated), so no grand total is shown.
